import { describe, expect, test, vi } from 'vitest';

import { createFactory } from './create_factory';
import { invoke } from './invoke';

describe('factories', () => {
  test('invoke calls original creator with passed params', () => {
    const mock = vi.fn();
    const factory = createFactory((params: number[]) => {
      mock(params);

      return params.at(0);
    });

    const valueOne = invoke(factory, [1, 2, 3]);
    expect(mock).toHaveBeenCalledWith([1, 2, 3]);
    expect(valueOne).toBe(1);

    const valueTwo = invoke(factory, [2, 3, 4]);
    expect(mock).toHaveBeenCalledWith([2, 3, 4]);
    expect(valueTwo).toBe(2);
  });

  test('throw error if try to call factory directly', () => {
    const myFactory = createFactory((params: number[]) => params.at(0));

    // @ts-expect-error It's obvious error, this test for JS-users
    expect(() => myFactory([1, 2, 3])).toThrowErrorMatchingInlineSnapshot(
      '"myFactory is not a function"'
    );
  });

  test('throw error if try to call internal creator directly', () => {
    const myFactory = createFactory((params: number[]) => params.at(0));

    expect(() =>
      myFactory.__.create([1, 2, 3])
    ).toThrowErrorMatchingInlineSnapshot(
      '"Do not call factory.__.create directly, pass factory to invoke function instead"'
    );
  });

  test('throw error if pass function with more than 1 argument', () => {
    expect(() =>
      // @ts-expect-error It's obvious error, this test for JS-users
      createFactory((first: number, second: number) => {
        return 1;
      })
    ).toThrowErrorMatchingInlineSnapshot(
      '"createFactory does not support functions with more than 1 argument"'
    );
  });
});
